Workbook

Sheet 係数一覧
A1: V2 工数係数一覧（概算見積） ※黄色の「変更値」に直したい値だけ入力。空欄は現行値を採用
A2: 工数 = 基本 + 台数 + 走行パターン + レイアウト(現地のみ) + 充電器 + 磁気停止 + ランドマーク + EV + 自動ドア + PLC信号 + 上位連携 → 最低=基本工数、0.5h単位切上げ。金額 = 工数 × 賃率
A4: 区分 | B4: 項目 | C4: DBフィールド | D4: 現行値 | E4: 変更値 | F4: 採用値 | G4: 単位 | H4: 意味・使われ方
A5: 賃率 | B5: 原価賃率 | C5: cost_hourly_rate | D5: 6820 | F5: =IF(E5="",D5,E5) | G5: 円/h | H5: 確定済み（工数×この値＝原価）
A6: 賃率 | B6: 販売賃率 | C6: sell_hourly_rate | D6: 12000 | F6: =IF(E6="",D6,E6) | G6: 円/h | H6: 確定済み（工数×この値＝販売額）
A7: 基本 | B7: 設計 基本工数 | C7: design_base_hours | D7: 8 | F7: =IF(E7="",D7,E7) | G7: h | H7: 最低工数。どんな案件でもこれ以上
A8: 基本 | B8: 現地 基本工数 | C8: setup_base_hours | D8: 8 | F8: =IF(E8="",D8,E8) | G8: h | H8: 最低工数
A9: 台数 | B9: 設計 台数あたり | C9: design_vehicle_hours | D9: 2 | F9: =IF(E9="",D9,E9) | G9: h/台 | H9: 台数×この値を加算
A10: 台数 | B10: 現地 台数あたり | C10: setup_vehicle_hours | D10: 4 | F10: =IF(E10="",D10,E10) | G10: h/台 | H10: 台数×この値を加算
A11: パターン | B11: 設計 パターン点あたり | C11: design_pattern_hours | D11: 3 | F11: =IF(E11="",D11,E11) | G11: h/点 | H11: 走行パターンスコア×この値
A12: パターン | B12: 現地 パターン点あたり | C12: setup_pattern_hours | D12: 4 | F12: =IF(E12="",D12,E12) | G12: h/点 | H12: 同上（現地デバッグ・検証）
A13: レイアウト | B13: 現地 エリア規模あたり | C13: setup_layout_scale_hours | D13: 1.5 | F13: =IF(E13="",D13,E13) | G13: h/点 | H13: √(短辺×長辺)÷10 × この値（現地のみ）
A14: ルート複雑さ | B14: simple | C14: route_factor_simple | D14: 1 | F14: =IF(E14="",D14,E14) | G14: 倍 | H14: 単純な搬送
A15: ルート複雑さ | B15: standard | C15: route_factor_standard | D15: 1.5 | F15: =IF(E15="",D15,E15) | G15: 倍
A16: ルート複雑さ | B16: complex | C16: route_factor_complex | D16: 2.3 | F16: =IF(E16="",D16,E16) | G16: 倍 | H16: 分岐・交差が多い
A17: ルート複雑さ | B17: unknown | C17: route_factor_unknown | D17: 1.6 | F17: =IF(E17="",D17,E17) | G17: 倍 | H17: 未確定時の安全側
A18: すれ違い・合流 | B18: low | C18: merge_factor_low | D18: 0.8 | F18: =IF(E18="",D18,E18) | G18: 倍
A19: すれ違い・合流 | B19: standard | C19: merge_factor_standard | D19: 1.3 | F19: =IF(E19="",D19,E19) | G19: 倍
A20: すれ違い・合流 | B20: high | C20: merge_factor_high | D20: 2 | F20: =IF(E20="",D20,E20) | G20: 倍 | H20: デッドロック検証が増える
A21: すれ違い・合流 | B21: unknown | C21: merge_factor_unknown | D21: 1.4 | F21: =IF(E21="",D21,E21) | G21: 倍
A22: 台数補正 | B22: 1台 | C22: vehicle_factor_one | D22: 1 | F22: =IF(E22="",D22,E22) | G22: 倍 | H22: パターンスコアに乗算
A23: 台数補正 | B23: 2台 | C23: vehicle_factor_two | D23: 1.4 | F23: =IF(E23="",D23,E23) | G23: 倍
A24: 台数補正 | B24: 3台 | C24: vehicle_factor_three | D24: 1.8 | F24: =IF(E24="",D24,E24) | G24: 倍
A25: 台数補正 | B25: 4台以上 | C25: vehicle_factor_four_or_more | D25: 2.2 | F25: =IF(E25="",D25,E25) | G25: 倍 | H25: 5台以上も同値（頭打ち）
A26: ランドマーク係数 | B26: small | C26: landmark_factor_small | D26: 1 | F26: =IF(E26="",D26,E26) | G26: 倍 | H26: ランドマークを使う範囲
A27: ランドマーク係数 | B27: medium | C27: landmark_factor_medium | D27: 1.8 | F27: =IF(E27="",D27,E27) | G27: 倍
A28: ランドマーク係数 | B28: large | C28: landmark_factor_large | D28: 2.8 | F28: =IF(E28="",D28,E28) | G28: 倍
A29: ランドマーク係数 | B29: full | C29: landmark_factor_full | D29: 4 | F29: =IF(E29="",D29,E29) | G29: 倍 | H29: 全域
A30: ランドマーク係数 | B30: unknown | C30: landmark_factor_unknown | D30: 2.2 | F30: =IF(E30="",D30,E30) | G30: 倍
A31: ランドマーク工数 | B31: 設計 係数あたり | C31: design_landmark_hours | D31: 1 | F31: =IF(E31="",D31,E31) | G31: h/点 | H31: ランドマーク係数×この値
A32: ランドマーク工数 | B32: 現地 係数あたり | C32: setup_landmark_hours | D32: 4 | F32: =IF(E32="",D32,E32) | G32: h/点
A33: 設備 | B33: 設計 充電器1台 | C33: design_charger_hours | D33: 1 | F33: =IF(E33="",D33,E33) | G33: h/台
A34: 設備 | B34: 現地 充電器1台 | C34: setup_charger_hours | D34: 2 | F34: =IF(E34="",D34,E34) | G34: h/台
A35: 設備 | B35: 設計 磁気停止1箇所 | C35: design_magnetic_stop_hours | D35: 0.5 | F35: =IF(E35="",D35,E35) | G35: h/箇所
A36: 設備 | B36: 現地 磁気停止1箇所 | C36: setup_magnetic_stop_hours | D36: 1 | F36: =IF(E36="",D36,E36) | G36: h/箇所
A37: 設備連携 | B37: 設計 EV 1基 | C37: design_elevator_hours | D37: 4 | F37: =IF(E37="",D37,E37) | G37: h/基
A38: 設備連携 | B38: 現地 EV 1基 | C38: setup_elevator_hours | D38: 5 | F38: =IF(E38="",D38,E38) | G38: h/基
A39: 設備連携 | B39: 設計 自動ドア1基 | C39: design_auto_door_hours | D39: 2 | F39: =IF(E39="",D39,E39) | G39: h/基
A40: 設備連携 | B40: 現地 自動ドア1基 | C40: setup_auto_door_hours | D40: 3 | F40: =IF(E40="",D40,E40) | G40: h/基
A41: 設備連携 | B41: 設計 PLC信号1点 | C41: design_plc_signal_hours | D41: 1.2 | F41: =IF(E41="",D41,E41) | G41: h/点
...

Sheet 試算
A1: 工数・金額の試算（係数一覧の採用値で自動計算。黄色の入力は自由に変更可）
A2: D〜F列はサンプル、G列は実案件用。シミュレーターから取れる値は右端「出力元」を参照
A4: 入力項目 | B4: キー | C4: 選択肢/単位 | D4: 小規模(例) | E4: 中規模(例) | F4: 大規模(例) | G4: 実案件用 | H4: シミュレーターの出力元
A5: AGV台数 | B5: vehicle_count | C5: 台 | D5: 1 | E5: 3 | F5: 6 | G5: 2 | H5: 必要台数逆算（capacity_planner）
A6: 受取ST数 | B6: pickup_count | C6: 箇所 | D6: 1 | E6: 2 | F6: 3 | G6: 1 | H6: 配置した受取ノード数
A7: 受渡ST数 | B7: dropoff_count | C7: 箇所 | D7: 1 | E7: 2 | F7: 4 | G7: 1 | H7: 配置した受渡ノード数
A8: 走行エリア 短辺 | B8: area_short_m | C8: m | D8: 10 | E8: 30 | F8: 60 | G8: 10 | H8: 走行エリア外形の短辺
A9: 走行エリア 長辺 | B9: area_long_m | C9: m | D9: 20 | E9: 50 | F9: 100 | G9: 20 | H9: 走行エリア外形の長辺
A10: ルート複雑さ | B10: route_complexity | C10: simple/standard/complex/unknown | D10: simple | E10: standard | F10: complex | G10: standard | H10: 分岐数・交差点数から判定（要ルール化）
A11: すれ違い・合流 | B11: merge_level | C11: low/standard/high/unknown | D11: low | E11: standard | F11: high | G11: standard | H11: 合流点・すれ違い点の数から判定（要ルール化）
A12: 充電器数 | B12: charger_count | C12: 台 | D12: 0 | E12: 1 | F12: 2 | G12: 0 | H12: 配置した充電ノード数
A13: 磁気停止数 | B13: magnetic_stop_count | C13: 箇所 | D13: 0 | E13: 0 | F13: 2 | G13: 0 | H13: （手入力）
A14: ランドマーク範囲 | B14: landmark_range | C14: small/medium/large/full/unknown | D14: small | E14: medium | F14: large | G14: unknown | H14: （手入力）
A15: EV数 | B15: elevator_count | C15: 基 | D15: 0 | E15: 0 | F15: 1 | G15: 0 | H15: （手入力）
A16: 自動ドア数 | B16: auto_door_count | C16: 基 | D16: 0 | E16: 1 | F16: 2 | G16: 0 | H16: （手入力）
A17: PLC連携規模 | B17: plc_scale | C17: none/small/medium/large/unknown | D17: none | E17: small | F17: medium | G17: none | H17: （手入力）
A18: 上位システム連携 | B18: host_system | C18: none/small/medium/large | D18: none | E18: none | F18: small | G18: none | H18: （手入力）
A20: ▼ 中間値
A21: パターン数(受取×受渡) | D21: =D$6*D$7 | E21: =E$6*E$7 | F21: =F$6*F$7 | G21: =G$6*G$7
A22: ルート係数 | D22: =CHOOSE(MATCH(D$10,{"simple","standard","complex","unknown"},0),'係数一覧'!$F$14,'係数一覧'!$F$15,'係数一覧'!$F$16,'係数一覧'!$F$17) | E22: =CHOOSE(MATCH(E$10,{"simple","standard","complex","unknown"},0),'係数一覧'!$F$14,'係数一覧'!$F$15,'係数一覧'!$F$16,'係数一覧'!$F$17) | F22: =CHOOSE(MATCH(F$10,{"simple","standard","complex","unknown"},0),'係数一覧'!$F$14,'係数一覧'!$F$15,'係数一覧'!$F$16,'係数一覧'!$F$17) | G22: =CHOOSE(MATCH(G$10,{"simple","standard","complex","unknown"},0),'係数一覧'!$F$14,'係数一覧'!$F$15,'係数一覧'!$F$16,'係数一覧'!$F$17)
A23: 合流係数 | D23: =CHOOSE(MATCH(D$11,{"low","standard","high","unknown"},0),'係数一覧'!$F$18,'係数一覧'!$F$19,'係数一覧'!$F$20,'係数一覧'!$F$21) | E23: =CHOOSE(MATCH(E$11,{"low","standard","high","unknown"},0),'係数一覧'!$F$18,'係数一覧'!$F$19,'係数一覧'!$F$20,'係数一覧'!$F$21) | F23: =CHOOSE(MATCH(F$11,{"low","standard","high","unknown"},0),'係数一覧'!$F$18,'係数一覧'!$F$19,'係数一覧'!$F$20,'係数一覧'!$F$21) | G23: =CHOOSE(MATCH(G$11,{"low","standard","high","unknown"},0),'係数一覧'!$F$18,'係数一覧'!$F$19,'係数一覧'!$F$20,'係数一覧'!$F$21)
A24: 台数係数 | D24: =IF(D$5<=1,'係数一覧'!$F$22,IF(D$5=2,'係数一覧'!$F$23,IF(D$5=3,'係数一覧'!$F$24,'係数一覧'!$F$25))) | E24: =IF(E$5<=1,'係数一覧'!$F$22,IF(E$5=2,'係数一覧'!$F$23,IF(E$5=3,'係数一覧'!$F$24,'係数一覧'!$F$25))) | F24: =IF(F$5<=1,'係数一覧'!$F$22,IF(F$5=2,'係数一覧'!$F$23,IF(F$5=3,'係数一覧'!$F$24,'係数一覧'!$F$25))) | G24: =IF(G$5<=1,'係数一覧'!$F$22,IF(G$5=2,'係数一覧'!$F$23,IF(G$5=3,'係数一覧'!$F$24,'係数一覧'!$F$25)))
A25: パターンスコア | D25: =SQRT(D21*D22*D23)*D24 | E25: =SQRT(E21*E22*E23)*E24 | F25: =SQRT(F21*F22*F23)*F24 | G25: =SQRT(G21*G22*G23)*G24
A26: レイアウトスコア | D26: =SQRT(D$8*D$9)/10 | E26: =SQRT(E$8*E$9)/10 | F26: =SQRT(F$8*F$9)/10 | G26: =SQRT(G$8*G$9)/10
A27: ランドマーク係数 | D27: =CHOOSE(MATCH(D$14,{"small","medium","large","full","unknown"},0),'係数一覧'!$F$26,'係数一覧'!$F$27,'係数一覧'!$F$28,'係数一覧'!$F$29,'係数一覧'!$F$30) | E27: =CHOOSE(MATCH(E$14,{"small","medium","large","full","unknown"},0),'係数一覧'!$F$26,'係数一覧'!$F$27,'係数一覧'!$F$28,'係数一覧'!$F$29,'係数一覧'!$F$30) | F27: =CHOOSE(MATCH(F$14,{"small","medium","large","full","unknown"},0),'係数一覧'!$F$26,'係数一覧'!$F$27,'係数一覧'!$F$28,'係数一覧'!$F$29,'係数一覧'!$F$30) | G27: =CHOOSE(MATCH(G$14,{"small","medium","large","full","unknown"},0),'係数一覧'!$F$26,'係数一覧'!$F$27,'係数一覧'!$F$28,'係数一覧'!$F$29,'係数一覧'!$F$30)
A28: PLC信号点数 | D28: =CHOOSE(MATCH(D$17,{"none","small","medium","large","unknown"},0),'係数一覧'!$F$43,'係数一覧'!$F$44,'係数一覧'!$F$45,'係数一覧'!$F$46,'係数一覧'!$F$47) | E28: =CHOOSE(MATCH(E$17,{"none","small","medium","large","unknown"},0),'係数一覧'!$F$43,'係数一覧'!$F$44,'係数一覧'!$F$45,'係数一覧'!$F$46,'係数一覧'!$F$47) | F28: =CHOOSE(MATCH(F$17,{"none","small","medium","large","unknown"},0),'係数一覧'!$F$43,'係数一覧'!$F$44,'係数一覧'!$F$45,'係数一覧'!$F$46,'係数一覧'!$F$47) | G28: =CHOOSE(MATCH(G$17,{"none","small","medium","large","unknown"},0),'係数一覧'!$F$43,'係数一覧'!$F$44,'係数一覧'!$F$45,'係数一覧'!$F$46,'係数一覧'!$F$47)
A29: 上位連携 設計h | D29: =CHOOSE(MATCH(D$18,{"none","small","medium","large"},0),'係数一覧'!$F$48,'係数一覧'!$F$49,'係数一覧'!$F$50,'係数一覧'!$F$51) | E29: =CHOOSE(MATCH(E$18,{"none","small","medium","large"},0),'係数一覧'!$F$48,'係数一覧'!$F$49,'係数一覧'!$F$50,'係数一覧'!$F$51) | F29: =CHOOSE(MATCH(F$18,{"none","small","medium","large"},0),'係数一覧'!$F$48,'係数一覧'!$F$49,'係数一覧'!$F$50,'係数一覧'!$F$51) | G29: =CHOOSE(MATCH(G$18,{"none","small","medium","large"},0),'係数一覧'!$F$48,'係数一覧'!$F$49,'係数一覧'!$F$50,'係数一覧'!$F$51)
A30: 上位連携 現地h | D30: =CHOOSE(MATCH(D$18,{"none","small","medium","large"},0),'係数一覧'!$F$52,'係数一覧'!$F$53,'係数一覧'!$F$54,'係数一覧'!$F$55) | E30: =CHOOSE(MATCH(E$18,{"none","small","medium","large"},0),'係数一覧'!$F$52,'係数一覧'!$F$53,'係数一覧'!$F$54,'係数一覧'!$F$55) | F30: =CHOOSE(MATCH(F$18,{"none","small","medium","large"},0),'係数一覧'!$F$52,'係数一覧'!$F$53,'係数一覧'!$F$54,'係数一覧'!$F$55) | G30: =CHOOSE(MATCH(G$18,{"none","small","medium","large"},0),'係数一覧'!$F$52,'係数一覧'!$F$53,'係数一覧'!$F$54,'係数一覧'!$F$55)
A32: ▼ 結果
A33: 設計工数 (h) | D33: =CEILING(MAX('係数一覧'!$F$7+D$5*'係数一覧'!$F$9+D25*'係数一覧'!$F$11+D$12*'係数一覧'!$F$33+D$13*'係数一覧'!$F$35+D27*'係数一覧'!$F$31+D$15*'係数一覧'!$F$37+D$16*'係数一覧'!$F$39+D28*'係数一覧'!$F$41+D29,'係数一覧'!$F$7),0.5) | E33: =CEILING(MAX('係数一覧'!$F$7+E$5*'係数一覧'!$F$9+E25*'係数一覧'!$F$11+E$12*'係数一覧'!$F$33+E$13*'係数一覧'!$F$35+E27*'係数一覧'!$F$31+E$15*'係数一覧'!$F$37+E$16*'係数一覧'!$F$39+E28*'係数一覧'!$F$41+E29,'係数一覧'!$F$7),0.5) | F33: =CEILING(MAX('係数一覧'!$F$7+F$5*'係数一覧'!$F$9+F25*'係数一覧'!$F$11+F$12*'係数一覧'!$F$33+F$13*'係数一覧'!$F$35+F27*'係数一覧'!$F$31+F$15*'係数一覧'!$F$37+F$16*'係数一覧'!$F$39+F28*'係数一覧'!$F$41+F29,'係数一覧'!$F$7),0.5) | G33: =CEILING(MAX('係数一覧'!$F$7+G$5*'係数一覧'!$F$9+G25*'係数一覧'!$F$11+G$12*'係数一覧'!$F$33+G$13*'係数一覧'!$F$35+G27*'係数一覧'!$F$31+G$15*'係数一覧'!$F$37+G$16*'係数一覧'!$F$39+G28*'係数一覧'!$F$41+G29,'係数一覧'!$F$7),0.5)
A34: 現地工数 (h) | D34: =CEILING(MAX('係数一覧'!$F$8+D$5*'係数一覧'!$F$10+D25*'係数一覧'!$F$12+D26*'係数一覧'!$F$13+D$12*'係数一覧'!$F$34+D$13*'係数一覧'!$F$36+D27*'係数一覧'!$F$32+D$15*'係数一覧'!$F$38+D$16*'係数一覧'!$F$40+D28*'係数一覧'!$F$42+D30,'係数一覧'!$F$8),0.5) | E34: =CEILING(MAX('係数一覧'!$F$8+E$5*'係数一覧'!$F$10+E25*'係数一覧'!$F$12+E26*'係数一覧'!$F$13+E$12*'係数一覧'!$F$34+E$13*'係数一覧'!$F$36+E27*'係数一覧'!$F$32+E$15*'係数一覧'!$F$38+E$16*'係数一覧'!$F$40+E28*'係数一覧'!$F$42+E30,'係数一覧'!$F$8),0.5) | F34: =CEILING(MAX('係数一覧'!$F$8+F$5*'係数一覧'!$F$10+F25*'係数一覧'!$F$12+F26*'係数一覧'!$F$13+F$12*'係数一覧'!$F$34+F$13*'係数一覧'!$F$36+F27*'係数一覧'!$F$32+F$15*'係数一覧'!$F$38+F$16*'係数一覧'!$F$40+F28*'係数一覧'!$F$42+F30,'係数一覧'!$F$8),0.5) | G34: =CEILING(MAX('係数一覧'!$F$8+G$5*'係数一覧'!$F$10+G25*'係数一覧'!$F$12+G26*'係数一覧'!$F$13+G$12*'係数一覧'!$F$34+G$13*'係数一覧'!$F$36+G27*'係数一覧'!$F$32+G$15*'係数一覧'!$F$38+G$16*'係数一覧'!$F$40+G28*'係数一覧'!$F$42+G30,'係数一覧'!$F$8),0.5)
A35: 合計工数 (h) | D35: =D33+D34 | E35: =E33+E34 | F35: =F33+F34 | G35: =G33+G34
A36: 設計 原価(円) | D36: =ROUND(D33*'係数一覧'!$F$5,0) | E36: =ROUND(E33*'係数一覧'!$F$5,0) | F36: =ROUND(F33*'係数一覧'!$F$5,0) | G36: =ROUND(G33*'係数一覧'!$F$5,0)
A37: 設計 販売(円) | D37: =ROUND(D33*'係数一覧'!$F$6,0) | E37: =ROUND(E33*'係数一覧'!$F$6,0) | F37: =ROUND(F33*'係数一覧'!$F$6,0) | G37: =ROUND(G33*'係数一覧'!$F$6,0)
A38: 現地 原価(円) | D38: =ROUND(D34*'係数一覧'!$F$5,0) | E38: =ROUND(E34*'係数一覧'!$F$5,0) | F38: =ROUND(F34*'係数一覧'!$F$5,0) | G38: =ROUND(G34*'係数一覧'!$F$5,0)
A39: 現地 販売(円) | D39: =ROUND(D34*'係数一覧'!$F$6,0) | E39: =ROUND(E34*'係数一覧'!$F$6,0) | F39: =ROUND(F34*'係数一覧'!$F$6,0) | G39: =ROUND(G34*'係数一覧'!$F$6,0)
A40: 合計 原価(円) | D40: =D36+D38 | E40: =E36+E38 | F40: =F36+F38 | G40: =G36+G38
A41: 合計 販売(円) | D41: =D37+D39 | E41: =E37+E39 | F41: =F37+F39 | G41: =G37+G39
A42: 粗利率 | D42: =IF(D41=0,0,(D41-D40)/D41) | E42: =IF(E41=0,0,(E41-E40)/E41) | F42: =IF(F41=0,0,(F41-F40)/F41) | G42: =IF(G41=0,0,(G41-G40)/G41)

Sheet 反映手順
A1: 1. 『係数一覧』の黄色「変更値」に直したい値を入力（変えない項目は空欄のまま）
A2: 2. 『試算』でサンプル案件の工数・金額が妥当か確認（妥当でなければ1へ）
A3: 3. 確定したらこのファイルを渡す → 見積アプリの管理画面 /admin/v2-parameters とDBへ反映
A4: ※ 賃率(原価6,820/販売12,000)は確定済みで反映済み
A5: ※ ルート複雑さ・合流の判定ルール(シミュレーターのどの数値でsimple/standard/complexとするか)は別途決める
